{
  "error": "1 validation error for NormalizationOutput\ntender\n  Field required [type=missing, input_value={'normalized_data': {}, '...': 'invalid_api_key'}}\"}, input_type=dict]\n    For further information visit https://errors.pydantic.dev/2.10/v/missing",
  "traceback": "Traceback (most recent call last):\n  File \"/Users/onelove/Downloads/python_normalizer/src/services/normalizer.py\", line 709, in _normalize_with_llm\n    output = NormalizationOutput(\n             ^^^^^^^^^^^^^^^^^^^^\n  File \"/Users/onelove/.pyenv/versions/3.12.3/lib/python3.12/site-packages/pydantic/main.py\", line 214, in __init__\n    validated_self = self.__pydantic_validator__.validate_python(data, self_instance=self)\n                     ^^^^^^^^^^^^^^^^^^^^^^^^^^^^^^^^^^^^^^^^^^^^^^^^^^^^^^^^^^^^^^^^^^^^^\npydantic_core._pydantic_core.ValidationError: 1 validation error for NormalizationOutput\ntender\n  Field required [type=missing, input_value={'normalized_data': {}, '...': 'invalid_api_key'}}\"}, input_type=dict]\n    For further information visit https://errors.pydantic.dev/2.10/v/missing\n"
}