{
  "error": "Error code: 401 - {'error': {'message': 'Incorrect API key provided: sk-your-********here. You can find your API key at https://platform.openai.com/account/api-keys.', 'type': 'invalid_request_error', 'param': None, 'code': 'invalid_api_key'}}",
  "traceback": "Traceback (most recent call last):\n  File \"/Users/onelove/Downloads/python_normalizer/src/services/direct_normalizer.py\", line 303, in normalize_tender\n    response = await self.client.chat.completions.create(\n               ^^^^^^^^^^^^^^^^^^^^^^^^^^^^^^^^^^^^^^^^^^\n  File \"/Users/onelove/.pyenv/versions/3.12.3/lib/python3.12/site-packages/openai/resources/chat/completions/completions.py\", line 1927, in create\n    return await self._post(\n           ^^^^^^^^^^^^^^^^^\n  File \"/Users/onelove/.pyenv/versions/3.12.3/lib/python3.12/site-packages/openai/_base_client.py\", line 1862, in post\n    return await self.request(cast_to, opts, stream=stream, stream_cls=stream_cls)\n           ^^^^^^^^^^^^^^^^^^^^^^^^^^^^^^^^^^^^^^^^^^^^^^^^^^^^^^^^^^^^^^^^^^^^^^^\n  File \"/Users/onelove/.pyenv/versions/3.12.3/lib/python3.12/site-packages/openai/_base_client.py\", line 1556, in request\n    return await self._request(\n           ^^^^^^^^^^^^^^^^^^^^\n  File \"/Users/onelove/.pyenv/versions/3.12.3/lib/python3.12/site-packages/openai/_base_client.py\", line 1657, in _request\n    raise self._make_status_error_from_response(err.response) from None\nopenai.AuthenticationError: Error code: 401 - {'error': {'message': 'Incorrect API key provided: sk-your-********here. You can find your API key at https://platform.openai.com/account/api-keys.', 'type': 'invalid_request_error', 'param': None, 'code': 'invalid_api_key'}}\n"
}